# 第09章 错误处理

## 1 `panic!`与不可恢复错误

* 程序`panic!`时，默认行为是展开（unwinding），但也可以选择终止（abort）

```
[profile.release]
panic = 'abort'
```

* 调试运行时，设置环境变量`RUST_BACKTRACE=1`，可以在`panic!`时显示详细的调用栈

```
$ RUST_BACKTRACE=1 cargo run
    Finished dev [unoptimized + debuginfo] target(s) in 0.0 secs
     Running `target/debug/panic`
thread 'main' panicked at 'index out of bounds: the len is 3 but the index is 99', /checkout/src/liballoc/vec.rs:1555:10
stack backtrace:
   0: std::sys::imp::backtrace::tracing::imp::unwind_backtrace
             at /checkout/src/libstd/sys/unix/backtrace/tracing/gcc_s.rs:49
   1: std::sys_common::backtrace::_print
             at /checkout/src/libstd/sys_common/backtrace.rs:71
   ......
```

## 2 `Result`与可恢复错误

* 标准库中的`std::result::Result`表示可恢复错误

```rust
pub enum Result<T, E> {
    Ok(T),
    Err(E),
}
```

```rust
use std::fs::File;
use std::io::ErrorKind;

pub fn main() {
	let f = File::open("hello.txt");
	let f = match f {
		Ok(file) => file,
		Err(ref error) if error.kind() == ErrorKind::NotFound => {
			match File::create("hello.txt") {
				Ok(fc) => fc,
				Err(e) => panic!("Tried to create file but there was a problem: {:?}",e),
			}
		},
		Err(error) => panic!("There was a problem opening the file: {:?}", error),
	};
}
```

### 2.1 失败时`panic`的简写：`unwrap`和`expect`

```rust
use std::fs::File;
fn main() {
    let f = File::open("hello.txt").unwrap();
}
```
```rust
use std::fs::File;
fn main() {
    let f = File::open("hello.txt").expect("Failed to open hello.txt");
}
```

### 2.2 传播错误

```rust
use std::io;
use std::io::Read;
use std::fs::File;
fn read_username_from_file() -> Result<String, io::Error> {
    let f = File::open("hello.txt");
    let mut f = match f {
        Ok(file) => file,
        Err(e) => return Err(e),
    };

    let mut s = String::new();
    match f.read_to_string(&mut s) {
        Ok(_) => Ok(s),
        Err(e) => Err(e),
    }
}
```

#### 2.2.1 传播错误的简写：`?`

* 注意：如果错误类型不同于返回的`Result`类型所需的错误类型，则尝试使用`From`特性来来进行类型转换
* 注意：`?`可以链式调用
* 注意：`?`只能用于返回`Result`类型的函数

```rust
use std::io;
use std::io::Read;
use std::fs::File;

fn read_username_from_file() -> Result<String, io::Error> {
    let mut f = File::open("hello.txt")?;
    let mut s = String::new();
    f.read_to_string(&mut s)?;
    Ok(s)
}

fn read_username_from_file2() -> Result<String, io::Error> {
    let mut s = String::new();
    File::open("hello.txt")?.read_to_string(&mut s)?;
    Ok(s)
}
```

### 2.3 `Result`类型的方法

* `Result<T,E>`
* `pub fn is_ok(&self) -> bool`
* `pub fn is_err(&self) -> bool`
* `pub fn ok(self) -> Option<T>`
* `pub fn err(self) -> Option<E>`

* `pub fn unwrap(self) -> T where E: Debug`// 注意: 错误类型E必须实现了Debug特性
* `pub fn expect(self, msg: &str) -> T where E: Debug`// 注意: 错误类型E必须实现了Debug特性

* `pub fn unwrap_err(self) -> E where T: Debug`// 注意: 反过来,返回E类型;如果成功则panic
* `pub fn expect_err(self) -> E where T: Debug`// 注意: 反过来,返回E类型;如果成功则panic

* `pub fn unwrap_or_default(self) -> T where T:Default`// 出错时返回默认值

* `pub fn unwrap_or(self, optb: T) -> T`// 出错则返回参数指定的值
* `pub fn unwrap_or_else<F: FnOnce(E) -> T>(self, op: F) -> T`// 出错则调用指定的函数转化错误

* `pub fn or<F>(self, res: Result<T, F>) -> Result<T, F>`
* `pub fn or_else<F, O: FnOnce(E) -> Result<T, F>>(self, op: O) -> Result<T, F>`

* `pub fn map<U, F: FnOnce(T) -> U>(self, op: F) -> Result<U,E>`// 映射成另一种T类型
* `pub fn map_err<F, O: FnOnce(E) -> F>(self, op: O) -> Result<T,F>`

## 3 何时使用`panic!`

* `panic!`会不可避免地导致进程异常退出，通常情况下返回`Result`类型更好
* 示例、代码原型、测试时适合使用`panic!`
* 比编译器知道得更多，明确知道不会出错时，可以调用`unwrap()`

```rust
use std::net::IpAddr;
let home: IpAddr = "127.0.0.1".parse().unwrap();
```